2024-10-07 13:37:20,691 INFO    MainThread:82906 [internal.py:wandb_internal():90] W&B internal server running at pid: 82906, started at: 2024-10-07 13:37:20.691200
2024-10-07 13:37:20,705 INFO    WriterThread:82906 [datastore.py:open_for_write():75] open: /home/xue/work/IsaacProduction/wandb/run-20241007_133719-9lr14kxv/run-9lr14kxv.wandb
2024-10-07 13:37:20,708 DEBUG   SenderThread:82906 [sender.py:send():236] send: header
2024-10-07 13:37:20,708 DEBUG   SenderThread:82906 [sender.py:send():236] send: run
2024-10-07 13:37:20,730 INFO    SenderThread:82906 [sender.py:_maybe_setup_resume():493] checking resume status for None/IsaacProduction/9lr14kxv
2024-10-07 13:37:21,442 ERROR   SenderThread:82906 [internal_api.py:execute():161] 403 response executing GraphQL.
2024-10-07 13:37:21,442 ERROR   SenderThread:82906 [internal_api.py:execute():162] {"errors":[{"message":"permission denied","path":["upsertBucket"],"extensions":{"code":"PERMISSION_ERROR"}}],"data":{"upsertBucket":null}}
2024-10-07 13:37:21,706 INFO    HandlerThread:82906 [handler.py:finish():806] shutting down handler
2024-10-07 13:37:21,706 INFO    WriterThread:82906 [datastore.py:close():279] close: /home/xue/work/IsaacProduction/wandb/run-20241007_133719-9lr14kxv/run-9lr14kxv.wandb
2024-10-07 13:37:21,707 ERROR   MainThread:82906 [internal.py:wandb_internal():165] Thread SenderThread:
Traceback (most recent call last):
  File "/home/xue/Repos/miniconda3/envs/isaac-sim/lib/python3.10/site-packages/wandb/sdk/lib/retry.py", line 108, in __call__
    result = self._call_fn(*args, **kwargs)
  File "/home/xue/Repos/miniconda3/envs/isaac-sim/lib/python3.10/site-packages/wandb/sdk/internal/internal_api.py", line 158, in execute
    return self.client.execute(*args, **kwargs)
  File "/home/xue/Repos/miniconda3/envs/isaac-sim/lib/python3.10/site-packages/wandb/vendor/gql-0.2.0/wandb_gql/client.py", line 52, in execute
    result = self._get_result(document, *args, **kwargs)
  File "/home/xue/Repos/miniconda3/envs/isaac-sim/lib/python3.10/site-packages/wandb/vendor/gql-0.2.0/wandb_gql/client.py", line 60, in _get_result
    return self.transport.execute(document, *args, **kwargs)
  File "/home/xue/Repos/miniconda3/envs/isaac-sim/lib/python3.10/site-packages/wandb/vendor/gql-0.2.0/wandb_gql/transport/requests.py", line 39, in execute
    request.raise_for_status()
  File "/home/xue/.local/share/ov/pkg/isaac-sim-2023.1.1/exts/omni.pip.cloud/pip_prebundle/requests/models.py", line 1021, in raise_for_status
    raise HTTPError(http_error_msg, response=self)
requests.exceptions.HTTPError: 403 Client Error: Forbidden for url: https://api.wandb.ai/graphql

During handling of the above exception, another exception occurred:

Traceback (most recent call last):
  File "/home/xue/Repos/miniconda3/envs/isaac-sim/lib/python3.10/site-packages/wandb/apis/normalize.py", line 25, in wrapper
    return func(*args, **kwargs)
  File "/home/xue/Repos/miniconda3/envs/isaac-sim/lib/python3.10/site-packages/wandb/sdk/internal/internal_api.py", line 1341, in upsert_run
    response = self.gql(mutation, variable_values=variable_values, **kwargs)
  File "/home/xue/Repos/miniconda3/envs/isaac-sim/lib/python3.10/site-packages/wandb/sdk/lib/retry.py", line 124, in __call__
    if not check_retry_fn(e):
  File "/home/xue/Repos/miniconda3/envs/isaac-sim/lib/python3.10/site-packages/wandb/util.py", line 887, in no_retry_auth
    raise CommError("Permission denied, ask the project owner to grant you access")
wandb.errors.CommError: Permission denied, ask the project owner to grant you access

During handling of the above exception, another exception occurred:

Traceback (most recent call last):
  File "/home/xue/Repos/miniconda3/envs/isaac-sim/lib/python3.10/site-packages/wandb/sdk/internal/internal_util.py", line 51, in run
    self._run()
  File "/home/xue/Repos/miniconda3/envs/isaac-sim/lib/python3.10/site-packages/wandb/sdk/internal/internal_util.py", line 102, in _run
    self._process(record)
  File "/home/xue/Repos/miniconda3/envs/isaac-sim/lib/python3.10/site-packages/wandb/sdk/internal/internal.py", line 310, in _process
    self._sm.send(record)
  File "/home/xue/Repos/miniconda3/envs/isaac-sim/lib/python3.10/site-packages/wandb/sdk/internal/sender.py", line 238, in send
    send_handler(record)
  File "/home/xue/Repos/miniconda3/envs/isaac-sim/lib/python3.10/site-packages/wandb/sdk/internal/sender.py", line 696, in send_run
    self._init_run(run, config_value_dict)
  File "/home/xue/Repos/miniconda3/envs/isaac-sim/lib/python3.10/site-packages/wandb/sdk/internal/sender.py", line 720, in _init_run
    server_run, inserted = self._api.upsert_run(
  File "/home/xue/Repos/miniconda3/envs/isaac-sim/lib/python3.10/site-packages/wandb/apis/normalize.py", line 61, in wrapper
    raise CommError(message, err).with_traceback(sys.exc_info()[2])
  File "/home/xue/Repos/miniconda3/envs/isaac-sim/lib/python3.10/site-packages/wandb/apis/normalize.py", line 25, in wrapper
    return func(*args, **kwargs)
  File "/home/xue/Repos/miniconda3/envs/isaac-sim/lib/python3.10/site-packages/wandb/sdk/internal/internal_api.py", line 1341, in upsert_run
    response = self.gql(mutation, variable_values=variable_values, **kwargs)
  File "/home/xue/Repos/miniconda3/envs/isaac-sim/lib/python3.10/site-packages/wandb/sdk/lib/retry.py", line 124, in __call__
    if not check_retry_fn(e):
  File "/home/xue/Repos/miniconda3/envs/isaac-sim/lib/python3.10/site-packages/wandb/util.py", line 887, in no_retry_auth
    raise CommError("Permission denied, ask the project owner to grant you access")
wandb.errors.CommError: Permission denied, ask the project owner to grant you access
2024-10-07 13:37:24,350 INFO    MainThread:82906 [internal.py:handle_exit():80] Internal process exited
